● deploy_service.service - Deployment web server
     Loaded: loaded (/etc/systemd/system/deploy_service.service; enabled; vendor preset: enabled)
     Active: active (running) since Tue 2021-04-13 12:43:08 UTC; 3min 54s ago
   Main PID: 2310 (deploy-service)
      Tasks: 1 (limit: 2344)
     Memory: 31.7M
     CGroup: /system.slice/deploy_service.service
             └─2310 /usr/bin/python3 /usr/local/bin/deploy-service

Apr 13 12:46:03 ubuntu-ci-lab deploy-service[2310]:   File "/usr/local/lib/python3.8/dist-packages/docker-5.0.0-py3.8.egg/docker/api/container.py", line 441, in create_container_from_config
Apr 13 12:46:03 ubuntu-ci-lab deploy-service[2310]:     return self._result(res, True)
Apr 13 12:46:03 ubuntu-ci-lab deploy-service[2310]:   File "/usr/local/lib/python3.8/dist-packages/docker-5.0.0-py3.8.egg/docker/api/client.py", line 274, in _result
Apr 13 12:46:03 ubuntu-ci-lab deploy-service[2310]:     self._raise_for_status(response)
Apr 13 12:46:03 ubuntu-ci-lab deploy-service[2310]:   File "/usr/local/lib/python3.8/dist-packages/docker-5.0.0-py3.8.egg/docker/api/client.py", line 270, in _raise_for_status
Apr 13 12:46:03 ubuntu-ci-lab deploy-service[2310]:     raise create_api_error_from_http_exception(e)
Apr 13 12:46:03 ubuntu-ci-lab deploy-service[2310]:   File "/usr/local/lib/python3.8/dist-packages/docker-5.0.0-py3.8.egg/docker/errors.py", line 31, in create_api_error_from_http_exception
Apr 13 12:46:03 ubuntu-ci-lab deploy-service[2310]:     raise cls(e, response=response, explanation=explanation)
Apr 13 12:46:03 ubuntu-ci-lab deploy-service[2310]: docker.errors.APIError: 400 Client Error for http+docker://localhost/v1.41/containers/create?name=emojiservice: Bad Request ("maximum retry count cannot be used with restart policy 'unless-stopped'")
Apr 13 12:46:03 ubuntu-ci-lab deploy-service[2310]: [2021-04-13 12:46:03,634] [ CD server ] [INFO]:werkzeug:40.65.216.235 - - [13/Apr/2021 12:46:03] "POST /deploy HTTP/1.1" 500 -
